[2016-07-03 19:33:32 +0000] [31284] [ERROR] Exception in worker process:
Traceback (most recent call last):
  File "/home/ckupitz/.virtualenvs/psiturk/local/lib/python2.7/site-packages/gunicorn/arbiter.py", line 515, in spawn_worker
    worker.init_process()
  File "/home/ckupitz/.virtualenvs/psiturk/local/lib/python2.7/site-packages/gunicorn/workers/base.py", line 122, in init_process
    self.load_wsgi()
  File "/home/ckupitz/.virtualenvs/psiturk/local/lib/python2.7/site-packages/gunicorn/workers/base.py", line 130, in load_wsgi
    self.wsgi = self.app.wsgi()
  File "/home/ckupitz/.virtualenvs/psiturk/local/lib/python2.7/site-packages/gunicorn/app/base.py", line 67, in wsgi
    self.callable = self.load()
  File "/home/ckupitz/.virtualenvs/psiturk/local/lib/python2.7/site-packages/psiturk/experiment_server.py", line 47, in load
    return util.import_app("psiturk.experiment:app")
  File "/home/ckupitz/.virtualenvs/psiturk/local/lib/python2.7/site-packages/gunicorn/util.py", line 357, in import_app
    __import__(module)
  File "/home/ckupitz/.virtualenvs/psiturk/local/lib/python2.7/site-packages/psiturk/experiment.py", line 84, in <module>
    init_db()
  File "/home/ckupitz/.virtualenvs/psiturk/local/lib/python2.7/site-packages/psiturk/db.py", line 37, in init_db
    Base.metadata.create_all(bind=engine)
  File "/home/ckupitz/.virtualenvs/psiturk/local/lib/python2.7/site-packages/sqlalchemy/schema.py", line 2848, in create_all
    tables=tables)
  File "/home/ckupitz/.virtualenvs/psiturk/local/lib/python2.7/site-packages/sqlalchemy/engine/base.py", line 1479, in _run_visitor
    conn._run_visitor(visitorcallable, element, **kwargs)
  File "/home/ckupitz/.virtualenvs/psiturk/local/lib/python2.7/site-packages/sqlalchemy/engine/base.py", line 1122, in _run_visitor
    **kwargs).traverse_single(element)
  File "/home/ckupitz/.virtualenvs/psiturk/local/lib/python2.7/site-packages/sqlalchemy/sql/visitors.py", line 122, in traverse_single
    return meth(obj, **kw)
  File "/home/ckupitz/.virtualenvs/psiturk/local/lib/python2.7/site-packages/sqlalchemy/engine/ddl.py", line 57, in visit_metadata
    if self._can_create_table(t)]
  File "/home/ckupitz/.virtualenvs/psiturk/local/lib/python2.7/site-packages/sqlalchemy/engine/ddl.py", line 35, in _can_create_table
    table.name, schema=table.schema)
  File "/home/ckupitz/.virtualenvs/psiturk/local/lib/python2.7/site-packages/sqlalchemy/dialects/mysql/base.py", line 2126, in has_table
    rs = connection.execute(st)
  File "/home/ckupitz/.virtualenvs/psiturk/local/lib/python2.7/site-packages/sqlalchemy/engine/base.py", line 662, in execute
    params)
  File "/home/ckupitz/.virtualenvs/psiturk/local/lib/python2.7/site-packages/sqlalchemy/engine/base.py", line 805, in _execute_text
    statement, parameters
  File "/home/ckupitz/.virtualenvs/psiturk/local/lib/python2.7/site-packages/sqlalchemy/engine/base.py", line 874, in _execute_context
    context)
  File "/home/ckupitz/.virtualenvs/psiturk/local/lib/python2.7/site-packages/sqlalchemy/engine/base.py", line 1024, in _handle_dbapi_exception
    exc_info
  File "/home/ckupitz/.virtualenvs/psiturk/local/lib/python2.7/site-packages/sqlalchemy/util/compat.py", line 196, in raise_from_cause
    reraise(type(exception), exception, tb=exc_tb)
  File "/home/ckupitz/.virtualenvs/psiturk/local/lib/python2.7/site-packages/sqlalchemy/engine/base.py", line 867, in _execute_context
    context)
  File "/home/ckupitz/.virtualenvs/psiturk/local/lib/python2.7/site-packages/sqlalchemy/engine/default.py", line 324, in do_execute
    cursor.execute(statement, parameters)
  File "/home/ckupitz/.virtualenvs/psiturk/local/lib/python2.7/site-packages/MySQLdb/cursors.py", line 205, in execute
    self.errorhandler(self, exc, value)
  File "/home/ckupitz/.virtualenvs/psiturk/local/lib/python2.7/site-packages/MySQLdb/connections.py", line 36, in defaulterrorhandler
    raise errorclass, errorvalue
OperationalError: (OperationalError) (1684, "Table 'nbpilot'.'nbpilotV1' was skipped since its definition is being modified by concurrent DDL statement") 'DESCRIBE `nbpilotV1`' ()
Traceback (most recent call last):
  File "/home/ckupitz/.virtualenvs/psiturk/local/lib/python2.7/site-packages/gunicorn/arbiter.py", line 515, in spawn_worker
    worker.init_process()
  File "/home/ckupitz/.virtualenvs/psiturk/local/lib/python2.7/site-packages/gunicorn/workers/base.py", line 122, in init_process
    self.load_wsgi()
  File "/home/ckupitz/.virtualenvs/psiturk/local/lib/python2.7/site-packages/gunicorn/workers/base.py", line 130, in load_wsgi
    self.wsgi = self.app.wsgi()
  File "/home/ckupitz/.virtualenvs/psiturk/local/lib/python2.7/site-packages/gunicorn/app/base.py", line 67, in wsgi
    self.callable = self.load()
  File "/home/ckupitz/.virtualenvs/psiturk/local/lib/python2.7/site-packages/psiturk/experiment_server.py", line 47, in load
    return util.import_app("psiturk.experiment:app")
  File "/home/ckupitz/.virtualenvs/psiturk/local/lib/python2.7/site-packages/gunicorn/util.py", line 357, in import_app
    __import__(module)
  File "/home/ckupitz/.virtualenvs/psiturk/local/lib/python2.7/site-packages/psiturk/experiment.py", line 84, in <module>
    init_db()
  File "/home/ckupitz/.virtualenvs/psiturk/local/lib/python2.7/site-packages/psiturk/db.py", line 37, in init_db
    Base.metadata.create_all(bind=engine)
  File "/home/ckupitz/.virtualenvs/psiturk/local/lib/python2.7/site-packages/sqlalchemy/schema.py", line 2848, in create_all
    tables=tables)
  File "/home/ckupitz/.virtualenvs/psiturk/local/lib/python2.7/site-packages/sqlalchemy/engine/base.py", line 1479, in _run_visitor
    conn._run_visitor(visitorcallable, element, **kwargs)
  File "/home/ckupitz/.virtualenvs/psiturk/local/lib/python2.7/site-packages/sqlalchemy/engine/base.py", line 1122, in _run_visitor
    **kwargs).traverse_single(element)
  File "/home/ckupitz/.virtualenvs/psiturk/local/lib/python2.7/site-packages/sqlalchemy/sql/visitors.py", line 122, in traverse_single
    return meth(obj, **kw)
  File "/home/ckupitz/.virtualenvs/psiturk/local/lib/python2.7/site-packages/sqlalchemy/engine/ddl.py", line 57, in visit_metadata
    if self._can_create_table(t)]
  File "/home/ckupitz/.virtualenvs/psiturk/local/lib/python2.7/site-packages/sqlalchemy/engine/ddl.py", line 35, in _can_create_table
    table.name, schema=table.schema)
  File "/home/ckupitz/.virtualenvs/psiturk/local/lib/python2.7/site-packages/sqlalchemy/dialects/mysql/base.py", line 2126, in has_table
    rs = connection.execute(st)
  File "/home/ckupitz/.virtualenvs/psiturk/local/lib/python2.7/site-packages/sqlalchemy/engine/base.py", line 662, in execute
    params)
  File "/home/ckupitz/.virtualenvs/psiturk/local/lib/python2.7/site-packages/sqlalchemy/engine/base.py", line 805, in _execute_text
    statement, parameters
  File "/home/ckupitz/.virtualenvs/psiturk/local/lib/python2.7/site-packages/sqlalchemy/engine/base.py", line 874, in _execute_context
    context)
  File "/home/ckupitz/.virtualenvs/psiturk/local/lib/python2.7/site-packages/sqlalchemy/engine/base.py", line 1024, in _handle_dbapi_exception
    exc_info
  File "/home/ckupitz/.virtualenvs/psiturk/local/lib/python2.7/site-packages/sqlalchemy/util/compat.py", line 196, in raise_from_cause
    reraise(type(exception), exception, tb=exc_tb)
  File "/home/ckupitz/.virtualenvs/psiturk/local/lib/python2.7/site-packages/sqlalchemy/engine/base.py", line 867, in _execute_context
    context)
  File "/home/ckupitz/.virtualenvs/psiturk/local/lib/python2.7/site-packages/sqlalchemy/engine/default.py", line 324, in do_execute
    cursor.execute(statement, parameters)
  File "/home/ckupitz/.virtualenvs/psiturk/local/lib/python2.7/site-packages/MySQLdb/cursors.py", line 205, in execute
    self.errorhandler(self, exc, value)
  File "/home/ckupitz/.virtualenvs/psiturk/local/lib/python2.7/site-packages/MySQLdb/connections.py", line 36, in defaulterrorhandler
    raise errorclass, errorvalue
OperationalError: (OperationalError) (1684, "Table 'nbpilot'.'nbpilotV1' was skipped since its definition is being modified by concurrent DDL statement") 'DESCRIBE `nbpilotV1`' ()
