2016-06-07 07:34:29,576 Exception on /ad [GET]
Traceback (most recent call last):
  File "/home/colin/.virtualenvs/psiturk/local/lib/python2.7/site-packages/flask/app.py", line 1817, in wsgi_app
    response = self.full_dispatch_request()
  File "/home/colin/.virtualenvs/psiturk/local/lib/python2.7/site-packages/flask/app.py", line 1477, in full_dispatch_request
    rv = self.handle_user_exception(e)
  File "/home/colin/.virtualenvs/psiturk/local/lib/python2.7/site-packages/flask/app.py", line 1381, in handle_user_exception
    reraise(exc_type, exc_value, tb)
  File "/home/colin/.virtualenvs/psiturk/local/lib/python2.7/site-packages/flask/app.py", line 1475, in full_dispatch_request
    rv = self.dispatch_request()
  File "/home/colin/.virtualenvs/psiturk/local/lib/python2.7/site-packages/flask/app.py", line 1461, in dispatch_request
    return self.view_functions[rule.endpoint](**req.view_args)
  File "/home/colin/.virtualenvs/psiturk/local/lib/python2.7/site-packages/psiturk/user_utils.py", line 20, in new_func
    resp = make_response(func(*args, **kwargs))
  File "/home/colin/.virtualenvs/psiturk/local/lib/python2.7/site-packages/psiturk/experiment.py", line 249, in advertisement
    filter(Participant.workerid == worker_id).\
  File "/home/colin/.virtualenvs/psiturk/local/lib/python2.7/site-packages/sqlalchemy/orm/query.py", line 2535, in count
    return self.from_self(col).scalar()
  File "/home/colin/.virtualenvs/psiturk/local/lib/python2.7/site-packages/sqlalchemy/orm/query.py", line 2341, in scalar
    ret = self.one()
  File "/home/colin/.virtualenvs/psiturk/local/lib/python2.7/site-packages/sqlalchemy/orm/query.py", line 2310, in one
    ret = list(self)
  File "/home/colin/.virtualenvs/psiturk/local/lib/python2.7/site-packages/sqlalchemy/orm/query.py", line 2353, in __iter__
    return self._execute_and_instances(context)
  File "/home/colin/.virtualenvs/psiturk/local/lib/python2.7/site-packages/sqlalchemy/orm/query.py", line 2368, in _execute_and_instances
    result = conn.execute(querycontext.statement, self._params)
  File "/home/colin/.virtualenvs/psiturk/local/lib/python2.7/site-packages/sqlalchemy/engine/base.py", line 662, in execute
    params)
  File "/home/colin/.virtualenvs/psiturk/local/lib/python2.7/site-packages/sqlalchemy/engine/base.py", line 761, in _execute_clauseelement
    compiled_sql, distilled_params
  File "/home/colin/.virtualenvs/psiturk/local/lib/python2.7/site-packages/sqlalchemy/engine/base.py", line 874, in _execute_context
    context)
  File "/home/colin/.virtualenvs/psiturk/local/lib/python2.7/site-packages/sqlalchemy/engine/base.py", line 1024, in _handle_dbapi_exception
    exc_info
  File "/home/colin/.virtualenvs/psiturk/local/lib/python2.7/site-packages/sqlalchemy/util/compat.py", line 196, in raise_from_cause
    reraise(type(exception), exception, tb=exc_tb)
  File "/home/colin/.virtualenvs/psiturk/local/lib/python2.7/site-packages/sqlalchemy/engine/base.py", line 867, in _execute_context
    context)
  File "/home/colin/.virtualenvs/psiturk/local/lib/python2.7/site-packages/sqlalchemy/engine/default.py", line 324, in do_execute
    cursor.execute(statement, parameters)
OperationalError: (OperationalError) no such table: npbilot u'SELECT count(*) AS count_1 \nFROM (SELECT npbilot.uniqueid AS npbilot_uniqueid, npbilot.assignmentid AS npbilot_assignmentid, npbilot.workerid AS npbilot_workerid, npbilot.hitid AS npbilot_hitid, npbilot.ipaddress AS npbilot_ipaddress, npbilot.browser AS npbilot_browser, npbilot.platform AS npbilot_platform, npbilot.language AS npbilot_language, npbilot.cond AS npbilot_cond, npbilot.counterbalance AS npbilot_counterbalance, npbilot.codeversion AS npbilot_codeversion, npbilot.beginhit AS npbilot_beginhit, npbilot.beginexp AS npbilot_beginexp, npbilot.endhit AS npbilot_endhit, npbilot.bonus AS npbilot_bonus, npbilot.status AS npbilot_status, npbilot.datastring AS npbilot_datastring \nFROM npbilot \nWHERE npbilot.assignmentid != ? AND npbilot.workerid = ?) AS anon_1' (u'debugQUTKLE', u'debugLION3G')
